Workbook

Sheet Đọc trước
B2: DX Living — dữ liệu báo cáo theo ngày
B3: Xuất ngày 2026-10-13 · nguồn: data/rollup.json của ba repo báo cáo
B5: File này là gì | C5: Bản xuất phẳng của dữ liệu đã lưu trong ba báo cáo DX Living, để đọc bằng tay và dựng báo cáo tháng. KHÔNG phải nguồn sự thật.
B6: Nguồn sự thật | C6: data/YYYY-MM-DD.json trong mỗi repo — bất biến, mỗi ngày một file, không bao giờ sửa. File Excel này và dashboard cùng đọc từ data/rollup.json, nên không bao giờ lệch nhau.
B7: Sửa file này thì sao | C7: Không ảnh hưởng gì tới báo cáo. Lần xuất sau sẽ ghi đè.
B9: BA LOẠI CHỈ SỐ — đọc kỹ trước khi cộng
B10: day | C10: Số đo của đúng ngày đó. CỘNG DỒN ĐƯỢC. Hiện chỉ Social có (Facebook và Instagram), dựng lại từ chuỗi 28 giá trị lưu sẵn trong mỗi file ngày.
B11: window28 | C11: Đã là tổng của 28 ngày trước đó. KHÔNG ĐƯỢC CỘNG — hai ngày liền nhau chồng nhau 27 ngày, cộng lại là đếm trùng nhiều lần. Chỉ so đầu kỳ với cuối kỳ.
B12: state | C12: Giá trị tại thời điểm quét (điểm số, tốc độ, số follower). Không cộng — lấy giá trị cuối kỳ hoặc trung bình.
B14: Ô trống | C14: Ngày đó không đo chỉ số này. Không suy ra, không điền 0.
B15: Ngày không quét | C15: Không bao giờ được nội suy. Ví dụ không có bản quét 20/09/2026.
B16: Meta điều chỉnh số | C16: Với chuỗi day của Social, mỗi ngày giữ lần đọc MỚI NHẤT — Meta có sửa số về sau.
B19: CÁC SHEET
B20: Social — theo ngày | C20: 100 dòng × 7 chỉ số · 2026-07-05 → 2026-10-12
B21: Social — 28 ngày | C21: 60 dòng × 14 chỉ số · 2026-07-23 → 2026-10-14
B22: SEO | C22: 60 dòng × 14 chỉ số · 2026-06-30 → 2026-10-14
B23: Audit | C23: 57 dòng × 11 chỉ số · 2026-07-27 → 2026-10-14

Sheet Social — theo ngày
A1: Social — theo ngày
A2: Số theo NGÀY THẬT — cộng dồn được. Dựng lại từ chuỗi 28 giá trị trong mỗi file ngày, giữ lần đọc mới nhất cho mỗi ngày.
A3: Nguồn: Social/data/rollup.json · 100 ngày · 7 chỉ số
A4: grain → | B4: day | C4: day | D4: day | E4: day | F4: day | G4: day | H4: day
A5: Ngày | B5: FB — tương tác/ngày | C5: FB — view 3 giây/ngày | D5: FB — views/ngày | E5: FB — lượt ghé/ngày | F5: IG — tương tác/ngày | G5: IG — reach/ngày | H5: IG — views/ngày
A6: 46208 | B6: 2 | C6: 0 | D6: 40 | E6: 1 | F6: 0 | G6: 0 | H6: 0
A7: 46209 | B7: 2 | C7: 1 | D7: 61 | E7: 0 | F7: 0 | G7: 0 | H7: 3
A8: 46210 | B8: 0 | C8: 0 | D8: 11 | E8: 1 | F8: 0 | G8: 0 | H8: 0
A9: 46211 | B9: 7 | C9: 1 | D9: 150 | E9: 1 | F9: 0 | G9: 2 | H9: 68
A10: 46212 | B10: 5 | C10: 1 | D10: 79 | E10: 0 | F10: 0 | G10: 1 | H10: 12
A11: 46213 | B11: 2 | C11: 1 | D11: 50 | E11: 0 | F11: 0 | G11: 2 | H11: 7
A12: 46214 | B12: 0 | C12: 1 | D12: 41 | E12: 3 | F12: 0 | G12: 1 | H12: 4
A13: 46215 | B13: 0 | C13: 1 | D13: 13 | E13: 1 | F13: 0 | G13: 1 | H13: 3
A14: 46216 | B14: 6 | C14: 7 | D14: 200 | E14: 7 | F14: 0 | G14: 0 | H14: 11
A15: 46217 | B15: 1 | C15: 0 | D15: 100 | E15: 7 | F15: 0 | G15: 2 | H15: 8
A16: 46218 | B16: 21 | C16: 0 | D16: 370 | E16: 17 | F16: 10 | G16: 9 | H16: 53
A17: 46219 | B17: 6 | C17: 0 | D17: 177 | E17: 3 | F17: 6 | G17: 26 | H17: 61
... A105: 46307 | B105: 2 | C105: 26 | D105: 201 | E105: 82 | F105: 1 | G105: 6 | H105: 129

Sheet Social — 28 ngày
A1: Social — 28 ngày
A2: Ảnh chụp cửa sổ 28 ngày và chỉ số trạng thái — KHÔNG cộng dồn. Chỉ so đầu kỳ với cuối kỳ.
A3: Nguồn: Social/data/rollup.json · 60 ngày · 14 chỉ số
A4: grain → | B4: state | C4: window28 | D4: window28 | E4: window28 | F4: state | G4: window28 | H4: window28 | I4: window28 | J4: state | K4: window28 | L4: window28 | M4: window28 | N4: state | O4: window28
A5: Ngày | B5: FB — followers | C5: FB — tương tác (28n) | D5: FB — views (28n) | E5: FB — lượt ghé (28n) | F5: IG — followers | G5: IG — tương tác (28n) | H5: IG — reach (28n) | I5: IG — views (28n) | J5: LinkedIn — followers | K5: LinkedIn — impressions (28n) | L5: LinkedIn — lượt xem trang (28n) | M5: LinkedIn — reactions (28n) | N5: YouTube — subscribers | O5: YouTube — views (28n)
A6: 46226 | B6: 113 | C6: 116 | D6: 2900 | E6: 130 | F6: 33 | G6: 27 | H6: 111 | I6: 665 | J6: 53 | K6: 1526 | L6: 37 | M6: 88 | N6: 4 | O6: 25
A7: 46230 | B7: 113 | C7: 115 | D7: 3100 | E7: 142 | F7: 33 | G7: 40 | H7: 180 | I7: 701 | J7: 54 | K7: 1366 | L7: 36 | M7: 54 | N7: 4 | O7: 27
A8: 46231 | B8: 113 | C8: 117 | D8: 3200 | E8: 142 | F8: 33 | G8: 42 | H8: 180 | I8: 720 | J8: 54 | K8: 1295 | L8: 36 | M8: 53 | N8: 4 | O8: 27
A9: 46232 | B9: 115 | C9: 113 | D9: 3200 | E9: 137 | F9: 33 | G9: 42 | H9: 180 | I9: 720 | J9: 54 | K9: 1287 | L9: 38 | M9: 54 | N9: 4 | O9: 27
A10: 46233 | B10: 115 | C10: 127 | D10: 3440 | E10: 160 | F10: 33 | G10: 48 | H10: 187 | I10: 810 | J10: 55 | K10: 1306 | L10: 41 | M10: 57 | N10: 4 | O10: 27
A11: 46234 | B11: 115 | C11: 130 | D11: 3635 | E11: 171 | F11: 33 | G11: 49 | H11: 192 | I11: 855 | J11: 55 | K11: 1351 | L11: 39 | M11: 56 | N11: 4 | O11: 28
A12: 46237 | B12: 115 | C12: 125 | D12: 3628 | E12: 192 | F12: 44 | G12: 52 | H12: 192 | I12: 872 | J12: 55 | K12: 1437 | L12: 44 | M12: 52 | N12: 4 | O12: 28
A13: 46238 | B13: 115 | C13: 123 | D13: 3675 | E13: 214 | F13: 44 | G13: 53 | H13: 192 | I13: 880 | J13: 55 | K13: 1456 | L13: 44 | M13: 52 | N13: 4 | O13: 28
A14: 46239 | B14: 115 | C14: 147 | D14: 4189 | E14: 253 | F14: 44 | G14: 55 | H14: 194 | I14: 937 | J14: 57 | K14: 1509 | L14: 40 | M14: 54 | N14: 4 | O14: 28
A15: 46240 | B15: 115 | C15: 157 | D15: 4438 | E15: 257 | F15: 44 | G15: 56 | H15: 194 | I15: 944 | J15: 58 | K15: 1692 | L15: 46 | M15: 58 | N15: 4 | O15: 28
A16: 46241 | B16: 115 | C16: 155 | D16: 4503 | E16: 264 | F16: 44 | G16: 60 | H16: 194 | I16: 897 | J16: 58 | K16: 1692 | L16: 46 | M16: 60 | N16: 4 | O16: 28
A17: 46244 | B17: 115 | C17: 168 | D17: 4777 | E17: 271 | F17: 44 | G17: 66 | H17: 196 | I17: 909 | J17: 58 | K17: 1680 | L17: 47 | M17: 65 | N17: 4 | O17: 28
... A54: 46295 | B54: 116 | C54: 141 | D54: 4519 | E54: 422 | F54: 49 | G54: 20 | H54: 87 | I54: 2258 | J54: 102 | K54: 1193 | L54: 24 | M54: 36 | N54: 4 | O54: 634
A55: 46296 | B55: 116 | C55: 132 | D55: 4427 | E55: 421 | F55: 49 | G55: 23 | H55: 87 | I55: 2297 | J55: 102 | K55: 1219 | L55: 26 | M55: 37
A56: 46297 | B56: 116 | C56: 140 | D56: 4339 | E56: 401 | F56: 49 | G56: 25 | H56: 90 | I56: 2409 | J56: 102 | K56: 1225 | L56: 27 | M56: 35 | N56: 6 | O56: 633
A57: 46298 | B57: 116 | C57: 157 | D57: 4412 | E57: 401 | F57: 49 | G57: 32 | H57: 116 | I57: 2610 | J57: 102 | K57: 1263 | L57: 33 | M57: 34 | N57: 7 | O57: 736
A58: 46300 | B58: 116 | C58: 158 | D58: 4404 | E58: 401 | F58: 49 | G58: 33 | H58: 117 | I58: 2616 | J58: 102 | K58: 1282 | L58: 33 | M58: 36 | N58: 7 | O58: 938
A59: 46301 | B59: 116 | C59: 158 | D59: 4380 | E59: 366 | F59: 49 | G59: 33 | H59: 117 | I59: 2610 | J59: 102 | K59: 1253 | L59: 31 | M59: 37 | N59: 7 | O59: 940
A60: 46302 | B60: 116 | C60: 201 | D60: 4418 | E60: 352 | F60: 49 | G60: 33 | H60: 119 | I60: 2707 | J60: 102 | K60: 1188 | L60: 29 | M60: 29 | N60: 7 | O60: 939
A61: 46303 | B61: 116 | C61: 198 | D61: 4680 | E61: 393 | F61: 49 | G61: 35 | H61: 114 | I61: 2794 | J61: 120 | K61: 1220 | L61: 29 | M61: 29 | N61: 7 | O61: 681
A62: 46304 | B62: 116 | C62: 197 | D62: 4362 | E62: 442 | F62: 49 | G62: 37 | H62: 117 | I62: 2466 | J62: 124 | K62: 1243 | L62: 30 | M62: 30 | N62: 7 | O62: 841
A63: 46307 | B63: 116 | C63: 190 | D63: 4238 | E63: 431 | F63: 49 | G63: 38 | H63: 119 | I63: 2250 | J63: 128 | K63: 1404 | L63: 59 | M63: 44 | N63: 7 | O63: 846
A64: 46308 | B64: 116 | C64: 190 | D64: 4156 | E64: 418 | F64: 49 | G64: 38 | H64: 119 | I64: 2218 | J64: 131 | K64: 1103 | L64: 58 | M64: 41 | N64: 7 | O64: 842
A65: 46309 | B65: 116 | C65: 184 | D65: 4139 | E65: 493 | F65: 49 | G65: 39 | H65: 120 | I65: 2169 | J65: 132 | K65: 1090 | L65: 59 | M65: 41 | N65: 7 | O65: 842

Sheet SEO
A1: SEO
A2: GSC/GA4 là cửa sổ 28 ngày trượt; Ahrefs, TTFB, sitemap là trạng thái. KHÔNG cộng dồn.
A3: Nguồn: SEO/data/rollup.json · 60 ngày · 14 chỉ số
A4: grain → | B4: state | C4: state | D4: state | E4: window28 | F4: window28 | G4: window28 | H4: window28 | I4: window28 | J4: window28 | K4: window28 | L4: window28 | M4: window28 | N4: state | O4: state
A5: Ngày | B5: Ahrefs — trích dẫn AI | C5: Ahrefs — backlinks | D5: Ahrefs — referring domains | E5: GA4 — engagement % | F5: GA4 — key events | G5: GA4 — sessions | H5: GA4 — users | I5: GSC — clicks | J5: GSC — CTR % | K5: GSC — impressions | L5: GSC — vị trí TB | M5: GSC — số truy vấn | N5: Sitemap — số URL | O5: TTFB trung bình (ms)
A6: 46203 | D6: 244 | E6: 18.9 | G6: 322 | H6: 205 | I6: 47 | J6: 8 | K6: 587 | L6: 13.8
A7: 46230 | D7: 244 | E7: 61.5 | F7: 42 | G7: 442 | I7: 65 | J7: 7.2 | K7: 900 | L7: 23.2
A8: 46231 | B8: 14 | C8: 333 | D8: 328 | E8: 63 | F8: 42 | G8: 435 | I8: 65 | J8: 7 | K8: 934 | L8: 23.7
A9: 46232 | B9: 14 | C9: 344 | D9: 339 | E9: 64.1 | F9: 42 | G9: 421 | I9: 63 | J9: 6.6 | K9: 952 | L9: 23.8 | M9: 113
A10: 46233 | B10: 14 | C10: 344 | D10: 339 | E10: 64.1 | F10: 42 | G10: 421 | I10: 65 | J10: 6.5 | K10: 1006 | L10: 23.7 | M10: 88
A11: 46234 | B11: 14 | C11: 346 | D11: 341 | E11: 66.7 | F11: 42 | G11: 405 | I11: 67 | J11: 6.5 | K11: 1032 | L11: 24.1 | M11: 92
A12: 46237 | B12: 19 | C12: 357 | D12: 352 | E12: 67.2 | F12: 38 | G12: 381 | I12: 68 | J12: 5.7 | K12: 1189 | L12: 26.2 | M12: 105
A13: 46241 | B13: 19 | C13: 372 | D13: 366 | E13: 67.6 | F13: 23 | G13: 287 | H13: 140 | I13: 72 | J13: 5.6 | K13: 1288 | L13: 29.6 | M13: 128 | N13: 75
A14: 46244 | B14: 18 | C14: 401 | D14: 395 | E14: 66.28 | F14: 21 | G14: 258 | H14: 131 | I14: 74 | J14: 5.5 | K14: 1337 | L14: 29.2 | M14: 136 | N14: 76
A15: 46245 | B15: 18 | C15: 404 | D15: 397 | E15: 65.04 | F15: 15 | G15: 246 | H15: 128 | I15: 72 | J15: 5.3 | K15: 1371 | L15: 29.4 | M15: 140 | N15: 77
A16: 46246 | B16: 18 | C16: 415 | D16: 404 | E16: 66.37 | F16: 15 | G16: 223 | H16: 114 | I16: 72 | J16: 5.1 | K16: 1415 | L16: 30.6 | M16: 148 | N16: 78
A17: 46247 | B17: 18 | C17: 418 | D17: 406 | E17: 67 | F17: 15 | G17: 203 | H17: 111 | I17: 79 | J17: 5.2 | K17: 1521 | L17: 30.4 | M17: 153 | N17: 79
A18: 46248 | B18: 18 | C18: 422 | D18: 410 | E18: 67.82 | F18: 13 | G18: 174 | H18: 97 | I18: 87 | J18: 5.4 | K18: 1604 | L18: 29.6 | M18: 147 | N18: 79
A19: 46251 | B19: 18 | C19: 438 | D19: 422 | E19: 62.75 | F19: 9 | G19: 153 | H19: 83 | I19: 77 | J19: 4.4 | K19: 1749 | L19: 29.2 | M19: 154 | N19: 80
A20: 46252 | B20: 18 | C20: 439 | D20: 423 | E20: 54.95 | F20: 9 | G20: 111 | H20: 59 | I20: 76 | J20: 4.3 | K20: 1761 | L20: 29.3 | M20: 152 | N20: 82
A21: 46253 | B21: 18 | C21: 440 | D21: 425 | E21: 56.25 | F21: 5 | G21: 112 | H21: 56 | N21: 81
A22: 46254 | B22: 17 | C22: 440 | D22: 425 | E22: 50 | F22: 3 | G22: 120 | H22: 59 | I22: 65 | J22: 3.6 | K22: 1829 | L22: 29.2 | M22: 151 | N22: 16
A23: 46255 | B23: 17 | C23: 441 | D23: 426 | E23: 45.11 | F23: 1 | G23: 133 | H23: 63 | I23: 63 | J23: 3.5 | K23: 1824 | L23: 29.1 | M23: 150 | N23: 16
A24: 46258 | B24: 19 | C24: 426 | D24: 412 | E24: 40.83 | F24: 2 | G24: 169 | H24: 81 | I24: 68 | J24: 3.7 | K24: 1849 | L24: 28 | M24: 151 | N24: 86
A25: 46259 | B25: 22 | C25: 424 | D25: 409 | E25: 40.64 | F25: 5 | G25: 251 | H25: 144 | I25: 68 | J25: 3.7 | K25: 1841 | L25: 27.9 | M25: 149 | N25: 86
A26: 46260 | B26: 22 | C26: 418 | D26: 403 | E26: 39.39 | F26: 9 | G26: 264 | H26: 151 | I26: 70 | J26: 3.8 | K26: 1837 | L26: 28.1 | M26: 150 | N26: 88
A27: 46261 | B27: 21 | C27: 407 | D27: 392 | E27: 40.22 | F27: 7 | G27: 276 | H27: 155 | I27: 66 | J27: 3.7 | K27: 1802 | L27: 28.2 | M27: 148 | N27: 91
A28: 46262 | B28: 20 | C28: 399 | D28: 385 | E28: 44.77 | F28: 7 | G28: 306 | H28: 169 | I28: 65 | J28: 3.5 | K28: 1836 | L28: 29.2 | M28: 158 | N28: 92 | O28: 1201
A29: 46263 | B29: 20 | C29: 382 | D29: 368 | E29: 42.58 | F29: 7 | G29: 357 | H29: 200 | I29: 65 | J29: 3.6 | K29: 1820 | L29: 29.4 | M29: 154 | N29: 94 | O29: 766
A30: 46265 | B30: 21 | C30: 364 | D30: 349 | E30: 42.93 | F30: 7 | G30: 375 | H30: 204 | I30: 67 | J30: 3.8 | K30: 1757 | L30: 29.4 | M30: 151 | N30: 95 | O30: 1022
A31: 46266 | B31: 22 | C31: 356 | D31: 340 | E31: 41.98 | F31: 7 | G31: 405 | H31: 222 | I31: 66 | J31: 3.8 | K31: 1718 | L31: 29.2 | M31: 148 | N31: 48 | O31: 500
A32: 46268 | B32: 20 | C32: 339 | D32: 322 | E32: 41.14 | F32: 7 | G32: 440 | H32: 254 | I32: 65 | J32: 3.9 | K32: 1657 | L32: 28.7 | M32: 136 | N32: 99 | O32: 1115
A33: 46269 | B33: 20 | C33: 334 | D33: 317 | E33: 41.77 | F33: 7 | G33: 462 | H33: 259 | I33: 62 | J33: 3.7 | K33: 1679 | L33: 29.1 | M33: 134 | N33: 100 | O33: 876
A34: 46270 | B34: 20 | C34: 329 | D34: 314 | E34: 41.86 | F34: 7 | G34: 485 | H34: 268 | I34: 64 | J34: 3.8 | K34: 1704 | L34: 29.4 | M34: 134 | N34: 101 | O34: 1173
A35: 46272 | B35: 20 | C35: 333 | D35: 317 | E35: 41.88 | F35: 7 | G35: 499 | H35: 280 | I35: 62 | J35: 3.6 | K35: 1713 | L35: 29.6 | M35: 133 | N35: 102 | O35: 892
A36: 46273 | B36: 21 | C36: 338 | D36: 317 | E36: 42.41 | F36: 7 | G36: 514 | H36: 285 | I36: 61 | J36: 3.6 | K36: 1681 | L36: 29.2 | M36: 133 | N36: 103 | O36: 1045
A37: 46274 | B37: 21 | C37: 336 | D37: 315 | E37: 42.75 | F37: 7 | G37: 538 | H37: 298 | I37: 61 | J37: 3.8 | K37: 1596 | L37: 28.5 | M37: 122 | N37: 104 | O37: 1000
A38: 46275 | B38: 21 | C38: 344 | D38: 320 | E38: 43.09 | F38: 7 | G38: 557 | H38: 307 | I38: 53 | J38: 3.4 | K38: 1546 | L38: 29.4 | M38: 107 | N38: 106 | O38: 1094
A39: 46276 | B39: 21 | C39: 354 | D39: 329 | E39: 42.91 | F39: 7 | G39: 571 | H39: 315 | I39: 48 | J39: 3.3 | K39: 1468 | L39: 30.3 | M39: 107 | N39: 106 | O39: 959
... A54: 46295 | B54: 16 | C54: 918 | D54: 882 | E54: 33.99 | F54: 4 | G54: 559 | H54: 394 | I54: 30 | J54: 2.8 | K54: 1056 | L54: 25.8 | M54: 80 | N54: 119 | O54: 342
...

Sheet Audit
A1: Audit
A2: Mỗi dòng là một lần crawl tại thời điểm. Điểm số và tốc độ — KHÔNG cộng dồn.
A3: Nguồn: Audit/data/rollup.json · 57 ngày · 11 chỉ số
A4: grain → | B4: state | C4: state | D4: state | E4: state | F4: state | G4: state | H4: state | I4: state | J4: state | K4: state | L4: state
A5: Ngày | B5: Content | C5: Crawlability | D5: Health score | E5: On-page / Meta | F5: Số trang crawl | G5: Performance / TTFB | H5: Sitemap — số URL | I5: Structured data | J5: TTFB trung bình (ms) | K5: TTFB trung vị (ms) | L5: Tổng số từ
A6: 46230 | B6: 78 | C6: 88 | D6: 82 | E6: 78 | F6: 36 | G6: 88 | H6: 67 | I6: 72
A7: 46231 | B7: 80 | C7: 90 | D7: 84 | E7: 78 | F7: 61 | G7: 92 | H7: 67 | I7: 74
A8: 46232 | B8: 80 | C8: 90 | D8: 84 | E8: 78 | F8: 61 | G8: 92 | H8: 67 | I8: 74
A9: 46233 | B9: 80 | C9: 90 | D9: 87 | E9: 79 | F9: 61 | G9: 93 | H9: 67 | I9: 88
A10: 46234 | B10: 77 | C10: 89 | D10: 84 | E10: 76 | F10: 68 | G10: 91 | H10: 67 | I10: 82
A11: 46237 | B11: 77 | C11: 89 | D11: 84 | E11: 76 | F11: 68 | G11: 90 | H11: 67 | I11: 80
A12: 46238 | B12: 77 | C12: 89 | D12: 84 | E12: 76 | F12: 68 | G12: 93 | H12: 67 | I12: 80
A13: 46239 | B13: 79 | C13: 88 | D13: 83 | E13: 76 | F13: 76 | G13: 87 | H13: 75 | I13: 81
A14: 46241 | B14: 79 | C14: 96 | D14: 88 | E14: 76 | F14: 76 | G14: 92 | H14: 75 | I14: 87
A15: 46244 | B15: 80 | C15: 96 | D15: 88 | E15: 76 | F15: 77 | G15: 94 | H15: 76 | I15: 87
A16: 46245 | B16: 80 | C16: 96 | D16: 89 | E16: 76 | F16: 78 | G16: 96 | H16: 77 | I16: 87
A17: 46246 | B17: 81 | C17: 96 | D17: 88 | E17: 76 | F17: 79 | G17: 93 | H17: 78 | I17: 87 | J17: 697
A18: 46247 | B18: 79 | C18: 96 | D18: 88 | E18: 76 | F18: 80 | G18: 94 | H18: 79 | I18: 87 | J18: 674
A19: 46248 | B19: 81 | C19: 96 | D19: 89 | E19: 76 | F19: 80 | G19: 95 | H19: 79 | I19: 87 | J19: 618
A20: 46251 | B20: 80 | C20: 96 | D20: 88 | E20: 76 | F20: 81 | G20: 94 | H20: 80 | I20: 87 | J20: 671
A21: 46252 | B21: 80 | C21: 96 | D21: 88 | E21: 76 | F21: 82 | G21: 92 | H21: 81 | I21: 87 | J21: 761
A22: 46253 | B22: 83 | C22: 92 | D22: 92 | E22: 91 | F22: 81 | G22: 93 | H22: 81 | I22: 96 | J22: 755
A23: 46254 | B23: 82 | C23: 67 | D23: 84 | E23: 91 | F23: 81 | G23: 87 | H23: 16 | I23: 96 | J23: 821
A24: 46255 | B24: 84 | C24: 67 | D24: 86 | E24: 91 | F24: 82 | G24: 94 | H24: 16 | I24: 96 | J24: 757
A25: 46258 | B25: 85 | C25: 94 | D25: 93 | E25: 91 | F25: 84 | G25: 95 | H25: 85 | I25: 96 | J25: 700
A26: 46259 | B26: 85 | C26: 95 | D26: 93 | E26: 91 | F26: 85 | G26: 96 | H26: 86 | I26: 96 | J26: 656
A27: 46260 | B27: 86 | C27: 97 | D27: 94 | E27: 91 | F27: 87 | G27: 94 | H27: 88 | I27: 96 | J27: 720
A28: 46261 | B28: 87 | C28: 97 | D28: 92 | E28: 91 | F28: 90 | G28: 86 | H28: 91 | I28: 96 | J28: 888
... A30: 46268 | B30: 89 | C30: 80 | D30: 88 | E30: 92 | F30: 97 | G30: 85 | H30: 98 | I30: 96 | J30: 924
A31: 46269 | B31: 89 | C31: 78 | D31: 87 | E31: 92 | G31: 85 | I31: 96 | J31: 932 | L31: 204862
A32: 46272 | B32: 90 | C32: 77 | D32: 88 | E32: 92 | F32: 101 | G32: 90 | I32: 96 | J32: 785 | L32: 210673
A33: 46273 | B33: 90 | C33: 77 | D33: 87 | E33: 92 | F33: 102 | G33: 87 | I33: 95 | J33: 877 | L33: 213007
A34: 46274 | B34: 90 | C34: 93 | D34: 91 | E34: 92 | F34: 103 | G34: 88 | I34: 94 | J34: 833 | K34: 738 | L34: 215236
A35: 46275 | B35: 90 | C35: 93 | D35: 90 | E35: 91 | F35: 104 | G35: 86 | H35: 105 | I35: 93 | J35: 869 | K35: 787 | L35: 216434
A36: 46276 | B36: 90 | C36: 93 | D36: 88 | E36: 91 | F36: 105 | G36: 78 | H36: 106 | I36: 92 | J36: 1091 | K36: 1034 | L36: 219115
A37: 46279 | B37: 90 | C37: 93 | D37: 92 | E37: 91 | F37: 108 | G37: 97 | H37: 109 | I37: 89 | J37: 571 | K37: 533 | L37: 224048
A38: 46280 | B38: 89 | C38: 93 | D38: 92 | E38: 91 | F38: 109 | G38: 98 | H38: 110 | I38: 88 | J38: 350 | K38: 287 | L38: 218216
A39: 46281 | B39: 90 | C39: 93 | D39: 93 | E39: 91 | F39: 111 | G39: 98 | H39: 112 | I39: 88 | J39: 344 | K39: 283 | L39: 222873
A40: 46282 | B40: 90 | C40: 93 | D40: 93 | E40: 91 | F40: 111 | G40: 99 | H40: 112 | I40: 88 | J40: 315 | K40: 265 | L40: 222873
A41: 46283 | B41: 91 | C41: 93 | D41: 93 | E41: 91 | F41: 112 | G41: 99 | H41: 113 | I41: 88 | J41: 309 | K41: 252 | L41: 224773
...

Sheet Tổng hợp tháng
A1: Tổng hợp theo tháng
A2: Mọi ô dưới đây là CÔNG THỨC trỏ về các sheet dữ liệu — sửa dữ liệu thì số này tự đổi.
A3: Chỉ chuỗi grain "day" mới được CỘNG (SUMIFS). window28 và state lấy GIÁ TRỊ NGÀY QUÉT CUỐI CÙNG của tháng (INDEX).
A5: CỘNG ĐƯỢC — số theo ngày thật (Social)
A6: Chỉ số | B6: 2026-07 | C6: 2026-08 | D6: 2026-09 | E6: 2026-10
A7: FB — tương tác/ngày | B7: =SUMIFS('Social — theo ngày'!B6:B105,'Social — theo ngày'!$A$6:$A$105,">="&DATE(2026,7,1),'Social — theo ngày'!$A$6:$A$105,"<="&DATE(2026,7,31)) -> 125 | C7: =SUMIFS('Social — theo ngày'!B6:B105,'Social — theo ngày'!$A$6:$A$105,">="&DATE(2026,8,1),'Social — theo ngày'!$A$6:$A$105,"<="&DATE(2026,8,31)) -> 195 | D7: =SUMIFS('Social — theo ngày'!B6:B105,'Social — theo ngày'!$A$6:$A$105,">="&DATE(2026,9,1),'Social — theo ngày'!$A$6:$A$105,"<="&DATE(2026,9,30)) -> 160 | E7: =SUMIFS('Social — theo ngày'!B6:B105,'Social — theo ngày'!$A$6:$A$105,">="&DATE(2026,10,1),'Social — theo ngày'!$A$6:$A$105,"<="&DATE(2026,10,31)) -> 94
A8: FB — view 3 giây/ngày | B8: =SUMIFS('Social — theo ngày'!C6:C105,'Social — theo ngày'!$A$6:$A$105,">="&DATE(2026,7,1),'Social — theo ngày'!$A$6:$A$105,"<="&DATE(2026,7,31)) -> 106 | C8: =SUMIFS('Social — theo ngày'!C6:C105,'Social — theo ngày'!$A$6:$A$105,">="&DATE(2026,8,1),'Social — theo ngày'!$A$6:$A$105,"<="&DATE(2026,8,31)) -> 147 | D8: =SUMIFS('Social — theo ngày'!C6:C105,'Social — theo ngày'!$A$6:$A$105,">="&DATE(2026,9,1),'Social — theo ngày'!$A$6:$A$105,"<="&DATE(2026,9,30)) -> 354 | E8: =SUMIFS('Social — theo ngày'!C6:C105,'Social — theo ngày'!$A$6:$A$105,">="&DATE(2026,10,1),'Social — theo ngày'!$A$6:$A$105,"<="&DATE(2026,10,31)) -> 243
A9: FB — views/ngày | B9: =SUMIFS('Social — theo ngày'!D6:D105,'Social — theo ngày'!$A$6:$A$105,">="&DATE(2026,7,1),'Social — theo ngày'!$A$6:$A$105,"<="&DATE(2026,7,31)) -> 3579 | C9: =SUMIFS('Social — theo ngày'!D6:D105,'Social — theo ngày'!$A$6:$A$105,">="&DATE(2026,8,1),'Social — theo ngày'!$A$6:$A$105,"<="&DATE(2026,8,31)) -> 4978 | D9: =SUMIFS('Social — theo ngày'!D6:D105,'Social — theo ngày'!$A$6:$A$105,">="&DATE(2026,9,1),'Social — theo ngày'!$A$6:$A$105,"<="&DATE(2026,9,30)) -> 4776 | E9: =SUMIFS('Social — theo ngày'!D6:D105,'Social — theo ngày'!$A$6:$A$105,">="&DATE(2026,10,1),'Social — theo ngày'!$A$6:$A$105,"<="&DATE(2026,10,31)) -> 2087
A10: FB — lượt ghé/ngày | B10: =SUMIFS('Social — theo ngày'!E6:E105,'Social — theo ngày'!$A$6:$A$105,">="&DATE(2026,7,1),'Social — theo ngày'!$A$6:$A$105,"<="&DATE(2026,7,31)) -> 189 | C10: =SUMIFS('Social — theo ngày'!E6:E105,'Social — theo ngày'!$A$6:$A$105,">="&DATE(2026,8,1),'Social — theo ngày'!$A$6:$A$105,"<="&DATE(2026,8,31)) -> 314 | D10: =SUMIFS('Social — theo ngày'!E6:E105,'Social — theo ngày'!$A$6:$A$105,">="&DATE(2026,9,1),'Social — theo ngày'!$A$6:$A$105,"<="&DATE(2026,9,30)) -> 425 | E10: =SUMIFS('Social — theo ngày'!E6:E105,'Social — theo ngày'!$A$6:$A$105,">="&DATE(2026,10,1),'Social — theo ngày'!$A$6:$A$105,"<="&DATE(2026,10,31)) -> 244
A11: IG — tương tác/ngày | B11: =SUMIFS('Social — theo ngày'!F6:F105,'Social — theo ngày'!$A$6:$A$105,">="&DATE(2026,7,1),'Social — theo ngày'!$A$6:$A$105,"<="&DATE(2026,7,31)) -> 51 | C11: =SUMIFS('Social — theo ngày'!F6:F105,'Social — theo ngày'!$A$6:$A$105,">="&DATE(2026,8,1),'Social — theo ngày'!$A$6:$A$105,"<="&DATE(2026,8,31)) -> 69 | D11: =SUMIFS('Social — theo ngày'!F6:F105,'Social — theo ngày'!$A$6:$A$105,">="&DATE(2026,9,1),'Social — theo ngày'!$A$6:$A$105,"<="&DATE(2026,9,30)) -> 25 | E11: =SUMIFS('Social — theo ngày'!F6:F105,'Social — theo ngày'!$A$6:$A$105,">="&DATE(2026,10,1),'Social — theo ngày'!$A$6:$A$105,"<="&DATE(2026,10,31)) -> 20
A12: IG — reach/ngày | B12: =SUMIFS('Social — theo ngày'!G6:G105,'Social — theo ngày'!$A$6:$A$105,">="&DATE(2026,7,1),'Social — theo ngày'!$A$6:$A$105,"<="&DATE(2026,7,31)) -> 275 | C12: =SUMIFS('Social — theo ngày'!G6:G105,'Social — theo ngày'!$A$6:$A$105,">="&DATE(2026,8,1),'Social — theo ngày'!$A$6:$A$105,"<="&DATE(2026,8,31)) -> 387 | D12: =SUMIFS('Social — theo ngày'!G6:G105,'Social — theo ngày'!$A$6:$A$105,">="&DATE(2026,9,1),'Social — theo ngày'!$A$6:$A$105,"<="&DATE(2026,9,30)) -> 177 | E12: =SUMIFS('Social — theo ngày'!G6:G105,'Social — theo ngày'!$A$6:$A$105,">="&DATE(2026,10,1),'Social — theo ngày'!$A$6:$A$105,"<="&DATE(2026,10,31)) -> 85
A13: IG — views/ngày | B13: =SUMIFS('Social — theo ngày'!H6:H105,'Social — theo ngày'!$A$6:$A$105,">="&DATE(2026,7,1),'Social — theo ngày'!$A$6:$A$105,"<="&DATE(2026,7,31)) -> 869 | C13: =SUMIFS('Social — theo ngày'!H6:H105,'Social — theo ngày'!$A$6:$A$105,">="&DATE(2026,8,1),'Social — theo ngày'!$A$6:$A$105,"<="&DATE(2026,8,31)) -> 1161 | D13: =SUMIFS('Social — theo ngày'!H6:H105,'Social — theo ngày'!$A$6:$A$105,">="&DATE(2026,9,1),'Social — theo ngày'!$A$6:$A$105,"<="&DATE(2026,9,30)) -> 2465 | E13: =SUMIFS('Social — theo ngày'!H6:H105,'Social — theo ngày'!$A$6:$A$105,">="&DATE(2026,10,1),'Social — theo ngày'!$A$6:$A$105,"<="&DATE(2026,10,31)) -> 959
A15: KHÔNG CỘNG — Social — 28 ngày (lấy ngày quét cuối tháng)
A16: Chỉ số | B16: 2026-07 | C16: 2026-08 | D16: 2026-09 | E16: 2026-10
A17: FB — followers | B17: ='Social — 28 ngày'!B11 -> 115 | C17: ='Social — 28 ngày'!B32 -> 115 | D17: ='Social — 28 ngày'!B54 -> 116 | E17: ='Social — 28 ngày'!B65 -> 116
A18: FB — tương tác (28n) | B18: ='Social — 28 ngày'!C11 -> 130 | C18: ='Social — 28 ngày'!C32 -> 184 | D18: ='Social — 28 ngày'!C54 -> 141 | E18: ='Social — 28 ngày'!C65 -> 184
A19: FB — views (28n) | B19: ='Social — 28 ngày'!D11 -> 3635 | C19: ='Social — 28 ngày'!D32 -> 4735 | D19: ='Social — 28 ngày'!D54 -> 4519 | E19: ='Social — 28 ngày'!D65 -> 4139
A20: FB — lượt ghé (28n) | B20: ='Social — 28 ngày'!E11 -> 171 | C20: ='Social — 28 ngày'!E32 -> 280 | D20: ='Social — 28 ngày'!E54 -> 422 | E20: ='Social — 28 ngày'!E65 -> 493
A21: IG — followers | B21: ='Social — 28 ngày'!F11 -> 33 | C21: ='Social — 28 ngày'!F32 -> 47 | D21: ='Social — 28 ngày'!F54 -> 49 | E21: ='Social — 28 ngày'!F65 -> 49
A22: IG — tương tác (28n) | B22: ='Social — 28 ngày'!G11 -> 49 | C22: ='Social — 28 ngày'!G32 -> 68 | D22: ='Social — 28 ngày'!G54 -> 20 | E22: ='Social — 28 ngày'!G65 -> 39
A23: IG — reach (28n) | B23: ='Social — 28 ngày'!H11 -> 192 | C23: ='Social — 28 ngày'!H32 -> 275 | D23: ='Social — 28 ngày'!H54 -> 87 | E23: ='Social — 28 ngày'!H65 -> 120
A24: IG — views (28n) | B24: ='Social — 28 ngày'!I11 -> 855 | C24: ='Social — 28 ngày'!I32 -> 1039 | D24: ='Social — 28 ngày'!I54 -> 2258 | E24: ='Social — 28 ngày'!I65 -> 2169
A25: LinkedIn — followers | B25: ='Social — 28 ngày'!J11 -> 55 | C25: ='Social — 28 ngày'!J32 -> 100 | D25: ='Social — 28 ngày'!J54 -> 102 | E25: ='Social — 28 ngày'!J65 -> 132
A26: LinkedIn — impressions (28n) | B26: ='Social — 28 ngày'!K11 -> 1351 | C26: ='Social — 28 ngày'!K32 -> 1691 | D26: ='Social — 28 ngày'!K54 -> 1193 | E26: ='Social — 28 ngày'!K65 -> 1090
A27: LinkedIn — lượt xem trang (28n) | B27: ='Social — 28 ngày'!L11 -> 39 | C27: ='Social — 28 ngày'!L32 -> 127 | D27: ='Social — 28 ngày'!L54 -> 24 | E27: ='Social — 28 ngày'!L65 -> 59
A28: LinkedIn — reactions (28n) | B28: ='Social — 28 ngày'!M11 -> 56 | C28: ='Social — 28 ngày'!M32 -> 86 | D28: ='Social — 28 ngày'!M54 -> 36 | E28: ='Social — 28 ngày'!M65 -> 41
A29: YouTube — subscribers | B29: ='Social — 28 ngày'!N11 -> 4 | C29: ='Social — 28 ngày'!N32 -> 4 | D29: ='Social — 28 ngày'!N54 -> 4 | E29: ='Social — 28 ngày'!N65 -> 7
A30: YouTube — views (28n) | B30: ='Social — 28 ngày'!O11 -> 28 | C30: ='Social — 28 ngày'!O32 -> 59 | D30: ='Social — 28 ngày'!O54 -> 634 | E30: ='Social — 28 ngày'!O65 -> 842
A32: KHÔNG CỘNG — SEO (lấy ngày quét cuối tháng)
A33: Chỉ số | B33: 2026-06 | C33: 2026-07 | D33: 2026-08 | E33: 2026-09 | F33: 2026-10
A34: Ahrefs — trích dẫn AI | B34: =SEO!B6 -> 0 | C34: =SEO!B11 -> 14 | D34: =SEO!B30 -> 21 | E34: =SEO!B54 -> 16 | F34: =SEO!B65 -> 14
A35: Ahrefs — backlinks | B35: =SEO!C6 -> 0 | C35: =SEO!C11 -> 346 | D35: =SEO!C30 -> 364 | E35: =SEO!C54 -> 918 | F35: =SEO!C65 -> 915
A36: Ahrefs — referring domains | B36: =SEO!D6 -> 244 | C36: =SEO!D11 -> 341 | D36: =SEO!D30 -> 349 | E36: =SEO!D54 -> 882 | F36: =SEO!D65 -> 879
A37: GA4 — engagement % | B37: =SEO!E6 -> 18.9 | C37: =SEO!E11 -> 66.7 | D37: =SEO!E30 -> 42.93 | E37: =SEO!E54 -> 33.99 | F37: =SEO!E65 -> 36.76
A38: GA4 — key events | B38: =SEO!F6 -> 0 | C38: =SEO!F11 -> 42 | D38: =SEO!F30 -> 7 | E38: =SEO!F54 -> 4 | F38: =SEO!F65 -> 7
A39: GA4 — sessions | B39: =SEO!G6 -> 322 | C39: =SEO!G11 -> 405 | D39: =SEO!G30 -> 375 | E39: =SEO!G54 -> 559 | F39: =SEO!G65 -> 672
A40: GA4 — users | B40: =SEO!H6 -> 205 | C40: =SEO!H11 -> 0 | D40: =SEO!H30 -> 204 | E40: =SEO!H54 -> 394 | F40: =SEO!H65 -> 448
A41: GSC — clicks | B41: =SEO!I6 -> 47 | C41: =SEO!I11 -> 67 | D41: =SEO!I30 -> 67 | E41: =SEO!I54 -> 30 | F41: =SEO!I65 -> 23
A42: GSC — CTR % | B42: =SEO!J6 -> 8 | C42: =SEO!J11 -> 6.5 | D42: =SEO!J30 -> 3.8 | E42: =SEO!J54 -> 2.8 | F42: =SEO!J65 -> 3.4
A43: GSC — impressions | B43: =SEO!K6 -> 587 | C43: =SEO!K11 -> 1032 | D43: =SEO!K30 -> 1757 | E43: =SEO!K54 -> 1056 | F43: =SEO!K65 -> 672
...
